Traceback (most recent call last):
  File "C:\Users\admin\miniconda3\Lib\site-packages\jupyter_cache\executors\utils.py", line 58, in single_nb_execution
    executenb(
  File "C:\Users\admin\miniconda3\Lib\site-packages\nbclient\client.py", line 1305, in execute
    return NotebookClient(nb=nb, resources=resources, km=km, **kwargs).execute()
           ^^^^^^^^^^^^^^^^^^^^^^^^^^^^^^^^^^^^^^^^^^^^^^^^^^^^^^^^^^^^^^^^^^^^^
  File "C:\Users\admin\miniconda3\Lib\site-packages\jupyter_core\utils\__init__.py", line 166, in wrapped
    return loop.run_until_complete(inner)
           ^^^^^^^^^^^^^^^^^^^^^^^^^^^^^^
  File "C:\Users\admin\miniconda3\Lib\asyncio\base_events.py", line 653, in run_until_complete
    return future.result()
           ^^^^^^^^^^^^^^^
  File "C:\Users\admin\miniconda3\Lib\site-packages\nbclient\client.py", line 705, in async_execute
    await self.async_execute_cell(
  File "C:\Users\admin\miniconda3\Lib\site-packages\nbclient\client.py", line 1058, in async_execute_cell
    await self._check_raise_for_error(cell, cell_index, exec_reply)
  File "C:\Users\admin\miniconda3\Lib\site-packages\nbclient\client.py", line 914, in _check_raise_for_error
    raise CellExecutionError.from_cell_and_msg(cell, exec_reply_content)
nbclient.exceptions.CellExecutionError: An error occurred while executing the following cell:
------------------
import numpy as np
import matplotlib.pyplot as plt

#se crea la funcion para graficar vectores

def graficarVectores(vecs, cols, alpha=1):
    
    plt.figure()
    #se dibuja eje Y
    plt.axvline(x=0, color = "grey", zorder = 0)
    #se dibuja eje X
    plt.axhline(y=0, color = "grey", zorder = 0)

    for i in range(len(vecs)):
        x = np.concatenate([[0,0], vecs[i]])
        plt.quiver(
            [x[0]],
            [x[1]],
            [x[2]],
            [x[3]],
            angles="xy", scale_units="xy", scale=1,
            color = cols[i],
            alpha = alpha
        )

#el vector(es) a graficar, debe pasarse como una lista
#el color(es) a emplear, debe pasarse como una lista de strings
------------------


[1;31m---------------------------------------------------------------------------[0m
[1;31mModuleNotFoundError[0m                       Traceback (most recent call last)
Cell [1;32mIn[3], line 2[0m
[0;32m      1[0m [38;5;28;01mimport[39;00m [38;5;21;01mnumpy[39;00m [38;5;28;01mas[39;00m [38;5;21;01mnp[39;00m
[1;32m----> 2[0m [38;5;28;01mimport[39;00m [38;5;21;01mmatplotlib[39;00m[38;5;21;01m.[39;00m[38;5;21;01mpyplot[39;00m [38;5;28;01mas[39;00m [38;5;21;01mplt[39;00m
[0;32m      4[0m [38;5;66;03m#se crea la funcion para graficar vectores[39;00m
[0;32m      6[0m [38;5;28;01mdef[39;00m [38;5;21mgraficarVectores[39m(vecs, cols, alpha[38;5;241m=[39m[38;5;241m1[39m):

[1;31mModuleNotFoundError[0m: No module named 'matplotlib'

