Traceback (most recent call last):
  File "C:\Users\admin\miniconda3\Lib\site-packages\jupyter_cache\executors\utils.py", line 58, in single_nb_execution
    executenb(
  File "C:\Users\admin\miniconda3\Lib\site-packages\nbclient\client.py", line 1305, in execute
    return NotebookClient(nb=nb, resources=resources, km=km, **kwargs).execute()
           ^^^^^^^^^^^^^^^^^^^^^^^^^^^^^^^^^^^^^^^^^^^^^^^^^^^^^^^^^^^^^^^^^^^^^
  File "C:\Users\admin\miniconda3\Lib\site-packages\jupyter_core\utils\__init__.py", line 166, in wrapped
    return loop.run_until_complete(inner)
           ^^^^^^^^^^^^^^^^^^^^^^^^^^^^^^
  File "C:\Users\admin\miniconda3\Lib\asyncio\base_events.py", line 653, in run_until_complete
    return future.result()
           ^^^^^^^^^^^^^^^
  File "C:\Users\admin\miniconda3\Lib\site-packages\nbclient\client.py", line 705, in async_execute
    await self.async_execute_cell(
  File "C:\Users\admin\miniconda3\Lib\site-packages\nbclient\client.py", line 1058, in async_execute_cell
    await self._check_raise_for_error(cell, cell_index, exec_reply)
  File "C:\Users\admin\miniconda3\Lib\site-packages\nbclient\client.py", line 914, in _check_raise_for_error
    raise CellExecutionError.from_cell_and_msg(cell, exec_reply_content)
nbclient.exceptions.CellExecutionError: An error occurred while executing the following cell:
------------------
#let's append the data to the list

print(my_data.append(my_data))
------------------


[1;31m---------------------------------------------------------------------------[0m
[1;31mAttributeError[0m                            Traceback (most recent call last)
[1;32m~\AppData\Local\Temp\ipykernel_6992\2681446758.py[0m in [0;36m?[1;34m()[0m
[0;32m      1[0m [1;31m#let's append the data to the list[0m[1;33m[0m[1;33m[0m[0m
[0;32m      2[0m [1;33m[0m[0m
[1;32m----> 3[1;33m [0mprint[0m[1;33m([0m[0mmy_data[0m[1;33m.[0m[0mappend[0m[1;33m([0m[0mmy_data[0m[1;33m)[0m[1;33m)[0m[1;33m[0m[1;33m[0m[0m
[0m
[1;32m~\miniconda3\Lib\site-packages\pandas\core\generic.py[0m in [0;36m?[1;34m(self, name)[0m
[0;32m   6198[0m             [1;32mand[0m [0mname[0m [1;32mnot[0m [1;32min[0m [0mself[0m[1;33m.[0m[0m_accessors[0m[1;33m[0m[1;33m[0m[0m
[0;32m   6199[0m             [1;32mand[0m [0mself[0m[1;33m.[0m[0m_info_axis[0m[1;33m.[0m[0m_can_hold_identifiers_and_holds_name[0m[1;33m([0m[0mname[0m[1;33m)[0m[1;33m[0m[1;33m[0m[0m
[0;32m   6200[0m         ):
[0;32m   6201[0m             [1;32mreturn[0m [0mself[0m[1;33m[[0m[0mname[0m[1;33m][0m[1;33m[0m[1;33m[0m[0m
[1;32m-> 6202[1;33m         [1;32mreturn[0m [0mobject[0m[1;33m.[0m[0m__getattribute__[0m[1;33m([0m[0mself[0m[1;33m,[0m [0mname[0m[1;33m)[0m[1;33m[0m[1;33m[0m[0m
[0m
[1;31mAttributeError[0m: 'DataFrame' object has no attribute 'append'

