Traceback (most recent call last):
  File "C:\Users\admin\miniconda3\Lib\site-packages\jupyter_cache\executors\utils.py", line 58, in single_nb_execution
    executenb(
  File "C:\Users\admin\miniconda3\Lib\site-packages\nbclient\client.py", line 1305, in execute
    return NotebookClient(nb=nb, resources=resources, km=km, **kwargs).execute()
           ^^^^^^^^^^^^^^^^^^^^^^^^^^^^^^^^^^^^^^^^^^^^^^^^^^^^^^^^^^^^^^^^^^^^^
  File "C:\Users\admin\miniconda3\Lib\site-packages\jupyter_core\utils\__init__.py", line 166, in wrapped
    return loop.run_until_complete(inner)
           ^^^^^^^^^^^^^^^^^^^^^^^^^^^^^^
  File "C:\Users\admin\miniconda3\Lib\asyncio\base_events.py", line 653, in run_until_complete
    return future.result()
           ^^^^^^^^^^^^^^^
  File "C:\Users\admin\miniconda3\Lib\site-packages\nbclient\client.py", line 705, in async_execute
    await self.async_execute_cell(
  File "C:\Users\admin\miniconda3\Lib\site-packages\nbclient\client.py", line 1058, in async_execute_cell
    await self._check_raise_for_error(cell, cell_index, exec_reply)
  File "C:\Users\admin\miniconda3\Lib\site-packages\nbclient\client.py", line 914, in _check_raise_for_error
    raise CellExecutionError.from_cell_and_msg(cell, exec_reply_content)
nbclient.exceptions.CellExecutionError: An error occurred while executing the following cell:
------------------
# Pre-defined lists
names = ['United States', 'Australia', 'Japan', 'India', 'Russia', 'Morocco', 'Egypt']
dr =  [True, False, False, False, True, True, True]
cpc = [809, 731, 588, 18, 200, 70, 45]

# Import pandas as pd
import pandas as pd

# Create dictionary my_dict with three key:value pairs: my_dict
my_dict = {"country":names, "drives_right":dr, "cars_per_cap":cpc}

# Build a DataFrame cars from my_dict: cars
cars = pd.DataFrame(my_dict)

# Print cars
print(cars)
------------------


[1;31m---------------------------------------------------------------------------[0m
[1;31mModuleNotFoundError[0m                       Traceback (most recent call last)
Cell [1;32mIn[1], line 7[0m
[0;32m      4[0m cpc [38;5;241m=[39m [[38;5;241m809[39m, [38;5;241m731[39m, [38;5;241m588[39m, [38;5;241m18[39m, [38;5;241m200[39m, [38;5;241m70[39m, [38;5;241m45[39m]
[0;32m      6[0m [38;5;66;03m# Import pandas as pd[39;00m
[1;32m----> 7[0m [38;5;28;01mimport[39;00m [38;5;21;01mpandas[39;00m [38;5;28;01mas[39;00m [38;5;21;01mpd[39;00m
[0;32m      9[0m [38;5;66;03m# Create dictionary my_dict with three key:value pairs: my_dict[39;00m
[0;32m     10[0m my_dict [38;5;241m=[39m {[38;5;124m"[39m[38;5;124mcountry[39m[38;5;124m"[39m:names, [38;5;124m"[39m[38;5;124mdrives_right[39m[38;5;124m"[39m:dr, [38;5;124m"[39m[38;5;124mcars_per_cap[39m[38;5;124m"[39m:cpc}

[1;31mModuleNotFoundError[0m: No module named 'pandas'

